Workbook

Sheet 2023
B1: Zarewa Aluminium And Plastics Ltd Kaduna | G1: Zarewa Aluminium And Plastics Ltd Kaduna | L1: Zarewa Aluminium And Plastics Ltd Kaduna | Q1: Zarewa Aluminium And Plastics Ltd Kaduna | V1: Zarewa Aluminium And Plastics Ltd Kaduna | AA1: Zarewa Aluminium And Plastics Ltd Kaduna | AF1: Zarewa Aluminium And Plastics Ltd Kaduna | AK1: Zarewa Aluminium And Plastics Ltd Kaduna
B2: Production Account for the month end May | G2: Production Account for the month end June | L2: Production Account for the month end July | Q2: Production Account for the month end August | V2: Production Account for the month end September | AA2: Production Account for the month end October | AF2: Production Account for the month end November | AK2: Production Account for the month end December
B3: Opening Stock | D3: 64643620 | G3: Opening Stock | I3: =C7 -> 122151270 | L3: Opening Stock | N3: =H7 -> 110032510 | Q3: Opening Stock | S3: =M7 -> 119085150 | V3: Opening Stock | X3: =R7 -> 109700300 | AA3: Opening Stock | AC3: =W7 -> 85764250 | AF3: Opening Stock | AH3: =AB7 -> 96485000 | AK3: Opening Stock | AM3: =AG7 -> 100928250
B4: Purchases | D4: 118594890 | G4: Purchases | I4: 48249230 | L4: Purchases | N4: 55512380 | Q4: Purchases | S4: 49559700 | V4: Purchases | X4: 27896591 | AA4: Purchases | AC4: 59739006 | AF4: Purchases | AH4: 29724603 | AK4: Purchases | AM4: 53505400
B5: Carriage Inward | D5: 1040000 | G5: Carriage Inward | I5: 454000 | L5: Carriage Inward | N5: 648500 | Q5: Carriage Inward | S5: 610000 | V5: Carriage Inward | X5: 453000 | AA5: Carriage Inward | AC5: 590200 | AF5: Carriage Inward | AH5: 270050 | AK5: Carriage Inward | AM5: 463000
D6: =SUM(D3:D5) -> 184278510 | I6: =SUM(I3:I5) -> 170854500 | N6: =SUM(N3:N5) -> 166193390 | S6: =SUM(S3:S5) -> 169254850 | X6: =SUM(X3:X5) -> 138049891 | AC6: =SUM(AC3:AC5) -> 146093456 | AH6: =SUM(AH3:AH5) -> 126479653 | AM6: =SUM(AM3:AM5) -> 154896650
B7: Closing Stock | C7: 122151270 | G7: Closing Stock | H7: 110032510 | L7: Closing Stock | M7: 119085150 | Q7: Closing Stock | R7: 109700300 | V7: Closing Stock | W7: 85764250 | AA7: Closing Stock | AB7: =96485000 -> 96485000 | AF7: Closing Stock | AG7: 100928250 | AK7: Closing Stock | AL7: 101533360
D8: =D6-C7 -> 62127240 | I8: =I6-H7 -> 60821990 | N8: =N6-M7 -> 47108240 | S8: =S6-R7 -> 59554550 | X8: =X6-W7 -> 52285641 | AC8: =AC6-AB7 -> 49608456 | AH8: =AH6-AG7 -> 25551403 | AM8: =AM6-AL7 -> 53363290
B10: Factory Overhead | G10: Factory Overhead | L10: Factory Overhead | Q10: Factory Overhead | V10: Factory Overhead | AA10: Factory Overhead | AF10: Factory Overhead | AK10: Factory Overhead
B11: Wages | C11: 196878.67 | G11: Wages | H11: 230000 | L11: Wages | M11: 239878.67 | Q11: Wages | R11: 326712 | V11: Wages | W11: 309212 | AA11: Wages | AB11: 398065.6 | AF11: Wages | AG11: 398065.6 | AK11: Wages | AL11: 398065.6
B12: Fuel & Lubricant | C12: 335400 | G12: Fuel & Lubricant | H12: 155000 | L12: Fuel & Lubricant | M12: 19500 | Q12: Fuel & Lubricant | R12: 248000 | V12: Fuel & Lubricant | W12: 210000 | AA12: Fuel & Lubricant | AB12: 204000 | AF12: Fuel & Lubricant | AG12: 255000 | AK12: Fuel & Lubricant | AL12: 38000
B13: Electricity Bill | C13: 9100 | G13: Electricity Bill | H13: 12700 | L13: Electricity Bill | M13: 13000 | Q13: Electricity Bill | R13: 15000 | V13: Electricity Bill | W13: 17000 | AA13: Electricity Bill | AB13: 14000 | AF13: Electricity Bill | AG13: 25500 | AK13: Electricity Bill | AL13: 30000
B14: Maintainace | C14: 495870 | G14: Maintainace | H14: 97000 | L14: Maintainace | M14: 988650 | Q14: Maintainace | R14: 834500 | V14: Maintainace | W14: 538400 | AA14: Maintainace | AB14: 1083600 | AF14: Maintainace | AG14: 130500 | AK14: Maintainace | AL14: 142800
B15: Depreciation | C15: 110000 | G15: Depreciation | H15: 110000 | L15: Depreciation | M15: 110000 | Q15: Depreciation | R15: 110000 | V15: Depreciation | W15: 110000 | AA15: Depreciation | AB15: 110000 | AF15: Depreciation | AG15: 110000 | AK15: Depreciation | AL15: 110000
C16: =SUM(C11:C15) -> 1147248.7 | H16: =SUM(H11:H15) -> 604700 | M16: =SUM(M11:M15) -> 1371028.7 | R16: =SUM(R11:R15) -> 1534212 | W16: =SUM(W11:W15) -> 1184612 | AB16: =SUM(AB11:AB15) -> 1809665.6 | AG16: =SUM(AG11:AG15) -> 919065.6 | AL16: =SUM(AL11:AL15) -> 718865.6
D17: =D8+C16 -> 63274489 | I17: =I8+H16 -> 61426690 | N17: =N8+M16 -> 48479269 | S17: =S8+R16 -> 61088762 | X17: =X8+W16 -> 53470253 | AC17: =AC8+AB16 -> 51418122 | AH17: =AH8+AG16 -> 26470469 | AM17: =AM8+AL16 -> 54082156
B23: Zarewa Aluminium And Plastics Ltd Kaduna | G23: Zarewa Aluminium And Plastics Ltd Kaduna | L23: Zarewa Aluminium And Plastics Ltd Kaduna | Q23: Zarewa Aluminium And Plastics Ltd Kaduna | V23: Zarewa Aluminium And Plastics Ltd Kaduna | AA23: Zarewa Aluminium And Plastics Ltd Kaduna | AF23: Zarewa Aluminium And Plastics Ltd Kaduna | AK23: Zarewa Aluminium And Plastics Ltd Kaduna
B24: Profit and Lost Account for the month end May | G24: Profit and Lost Account for the month end June | L24: Profit and Lost Account for the month end July | Q24: Profit and Lost Account for the month end Agust | V24: Profit and Lost Account for the month end September | AA24: Profit and Lost Account for the month end October | AF24: Profit and Lost Account for the month end November | AK24: Profit and Lost Account for the month end November
B25: Opening Stock | G25: Opening Stock | L25: Opening Stock | Q25: Opening Stock | V25: Opening Stock | AA25: Opening Stock | AF25: Opening Stock | AK25: Opening Stock
B26: Sales | D26: 86357548 | G26: Sales | I26: 62723747 | L26: Sales | N26: 56990608 | Q26: Sales | S26: 74826072 | V26: Sales | X26: 58468327 | AA26: Sales | AC26: 62757181 | AF26: Sales | AH26: 41604347 | AK26: Sales | AM26: 58501640
B27: Refund | C27: 8308581.2 | G27: Refund | H27: 6820595 | L27: Refund | M27: 5149904 | Q27: Refund | R27: 8725755 | V27: Refund | W27: 3474605 | AA27: Refund | AB27: 4351875 | AF27: Refund | AG27: 3626054 | AK27: Refund | AL27: 8313258
B28: Net Sales | D28: =D26-C27 -> 78048967 | G28: Net Sales | I28: =I26-H27 -> 55903152 | L28: Net Sales | N28: =N26-M27 -> 51840704 | Q28: Net Sales | S28: =S26-R27 -> 66100318 | V28: Net Sales | X28: =X26-W27 -> 54993722 | AA28: Net Sales | AC28: =AC26-AB27 -> 58405306 | AF28: Net Sales | AH28: =AH26-AG27 -> 37978293 | AK28: Net Sales | AM28: =AM26-AL27 -> 50188382
B29: Production Cost | C29: =D17 -> 63274489 | G29: Production Cost | H29: =I17 -> 61426690 | L29: Production Cost | M29: =N17 -> 48479269 | Q29: Production Cost | R29: =S17 -> 61088762 | V29: Production Cost | W29: =X17 -> 53470253 | AA29: Production Cost | AB29: =AC17 -> 51418122 | AF29: Production Cost | AG29: =AH17 -> 26470469 | AK29: Production Cost | AL29: =AM17 -> 54082156
B30: Closing Stock | C30: 0 | G30: Closing Stock | H30: 0 | L30: Closing Stock | M30: 0 | Q30: Closing Stock | R30: 0 | V30: Closing Stock | W30: 0 | AA30: Closing Stock | AB30: 0 | AF30: Closing Stock | AG30: 0 | AK30: Closing Stock | AL30: 0
C31: =SUM(C29:C30) -> 63274489 | H31: =SUM(H29:H30) -> 61426690 | M31: =SUM(M29:M30) -> 48479269 | R31: =SUM(R29:R30) -> 61088762 | W31: =SUM(W29:W30) -> 53470253 | AB31: =SUM(AB29:AB30) -> 51418122 | AG31: =SUM(AG29:AG30) -> 26470469 | AL31: =SUM(AL29:AL30) -> 54082156
B32: Gross Profit | D32: =D28-C31 -> 14774478 | G32: Gross Profit | I32: =I28-H31 -> -5523538 | L32: Gross Profit | N32: =N28-M31 -> 3361435.3 | Q32: Gross Profit | S32: =S28-R31 -> 5011555.5 | V32: Gross Profit | X32: =X28-W31 -> 1523469 | AA32: Gross Profit | AC32: =AC28-AB31 -> 6987184.4 | AF32: Gross Profit | AH32: =AH28-AG31 -> 11507824 | AK32: Gross Profit | AM32: =AM28-AL31 -> -3893774.1
B34: Admin Expenses | G34: Admin Expenses | L34: Admin Expenses | Q34: Admin Expenses | V34: Admin Expenses | AA34: Admin Expenses | AF34: Admin Expenses | AK34: Admin Expenses
B35: Admin exp | C35: 56000 | G35: Admin exp | H35: 15000 | L35: Admin exp | M35: 10000 | Q35: Admin exp | R35: 62000 | V35: Admin exp | W35: 195000 | AA35: Admin exp | AB35: 27500 | AF35: Admin exp | AG35: 204700 | AK35: Admin exp | AL35: 0
B36: Admin Salary | C36: 526921.13 | G36: Admin Salary | H36: 584847 | L36: Admin Salary | M36: 536556.8 | Q36: Admin Salary | R36: 398065.6 | V36: Admin Salary | W36: 398065 | AA36: Admin Salary | AB36: 313878.67 | AF36: Admin Salary | AG36: 313878.67 | AK36: Admin Salary | AL36: 313878.67
B37: Bank Charge | C37: 126939.29 | G37: Bank Charge | H37: 0 | L37: Bank Charge | M37: 73004.69 | Q37: Bank Charge | R37: 82076.99 | V37: Bank Charge | W37: 45702.39 | AA37: Bank Charge | AB37: 78074.19 | AF37: Bank Charge | AG37: 46724.7 | AK37: Bank Charge | AL37: 25873.35
B38: Office Expenses | C38: 47000 | G38: Office Expenses | H38: 652200 | L38: Office Expenses | M38: 300675 | Q38: Office Expenses | R38: 69300 | V38: Office Expenses | W38: 119400 | AA38: Office Expenses | AB38: 76200 | AF38: Office Expenses | AG38: 91900 | AK38: Office Expenses | AL38: 224000
B39: Professional Fee | C39: 230000 | G39: Professional Fee | H39: 290000 | L39: Professional Fee | M39: 0 | Q39: Professional Fee | R39: 50000 | V39: Professional Fee | W39: 0 | AA39: Professional Fee | AB39: 0 | AF39: Professional Fee | AG39: 150000 | AK39: Professional Fee | AL39: 20000
B40: Tax | C40: 386302.31 | G40: Tax | H40: 176064.93 | L40: Tax | M40: 170000 | Q40: Tax | R40: 170000 | V40: Tax | W40: 540577 | AA40: Tax | AB40: 0 | AF40: Tax | AG40: 197000 | AK40: Tax | AL40: 5420000
B41: Pension | C41: 0 | G41: Pension | H41: 0 | L41: Pension | M41: 0 | Q41: Pension | R41: 0 | V41: Pension | W41: 0 | AA41: Pension | AB41: 0 | AF41: Pension | AG41: 0 | AK41: Pension | AL41: 52130
B42: Security | C42: 60000 | G42: Security | H42: 60000 | L42: Security | M42: 40000 | Q42: Security | R42: 25000 | V42: Security | W42: 25000 | AA42: Security | AB42: 25000 | AF42: Security | AG42: 25000 | AK42: Security | AL42: 25000
B43: Intrest | C43: 0 | G43: Intrest | H43: 0 | L43: Intrest | M43: 0 | Q43: Intrest | R43: 0 | V43: Intrest | W43: 0 | AA43: Intrest | AB43: 0 | AF43: Intrest | AG43: 0 | AK43: Intrest | AL43: 0
B44: Welfare | C44: 0 | G44: Welfare | H44: 0 | L44: Welfare | M44: 0 | Q44: Welfare | R44: 0 | V44: Welfare | W44: 0 | AA44: Welfare | AB44: 0 | AF44: Welfare | AG44: 0 | AK44: Welfare | AL44: 473000
B45: Zakat & Sallah | C45: 0 | G45: Zakat & Sallah | H45: 0 | L45: Zakat & Sallah | M45: 0 | Q45: Zakat & Sallah | R45: 0 | V45: Zakat & Sallah | W45: 0 | AA45: Zakat & Sallah | AB45: 0 | AF45: Zakat & Sallah | AG45: 0 | AK45: Zakat & Sallah | AL45: 0
C46: =SUM(C35:C45) -> 1433162.7 | H46: =SUM(H35:H45) -> 1778111.9 | M46: =SUM(M35:M45) -> 1130236.5 | R46: =SUM(R35:R45) -> 856442.59 | W46: =SUM(W35:W45) -> 1323744.4 | AB46: =SUM(AB35:AB45) -> 520652.86 | AG46: =SUM(AG35:AG45) -> 1029203.4 | AL46: =SUM(AL35:AL45) -> 6553882
B47: Net Profit | D47: =D32-C46 -> 13341316 | G47: Net Profit | I47: =I32-H46 -> -7301649.9 | L47: Net Profit | N47: =N32-M46 -> 2231198.8 | Q47: Net Profit | S47: =S32-R46 -> 4155112.9 | V47: Net Profit | X47: =X32-W46 -> 199724.61 | AA47: Net Profit | AC47: =AC32-AB46 -> 6466531.5 | AF47: Net Profit | AH47: =AH32-AG46 -> 10478621 | AK47: Net Profit | AM47: =AM32-AL46 -> -10447656
...

Sheet 2024
AW1: Zarewa Aluminium And Plastics Ltd Kaduna
A2: Zarewa Aluminium And Plastics Ltd Kaduna | E2: Zarewa Aluminium And Plastics Ltd Kaduna | I2: Zarewa Aluminium And Plastics Ltd Kaduna | M2: Zarewa Aluminium And Plastics Ltd Kaduna | Q2: Zarewa Aluminium And Plastics Ltd Kaduna | U2: Zarewa Aluminium And Plastics Ltd Kaduna | Y2: Zarewa Aluminium And Plastics Ltd Kaduna | AC2: Zarewa Aluminium And Plastics Ltd Kaduna | AH2: Zarewa Aluminium And Plastics Ltd Kaduna | AM2: Zarewa Aluminium And Plastics Ltd Kaduna | AR2: Zarewa Aluminium And Plastics Ltd Kaduna | AW2: Production Account for the month end December
A3: Production Account for the month end January | E3: Production Account for the month end Febuary | I3: Production Account for the month end MARCH | M3: Production Account for the month end April | Q3: Production Account for the month end May | U3: Production Account for the month end June | Y3: Production Account for the month end JuLY | AC3: Production Account for the month end August | AH3: Production Account for the month end September | AM3: Production Account for the month end October | AR3: Production Account for the month end Novemebr | AW3: Opening Stock | AY3: =AS8 -> 177934700
A4: Opening Stock | C4: =101533360 -> 101533360 | E4: Opening Stock | G4: =B8 -> 106588500 | I4: Opening Stock | K4: =F8 -> 104326450 | M4: Opening Stock | O4: =J8 -> 172746600 | Q4: Opening Stock | S4: =N8 -> 182105250 | U4: Opening Stock | W4: =R8 -> 219791680 | Y4: Opening Stock | AA4: =V8 -> 198432160 | AC4: Opening Stock | AE4: =Z8 -> 139718400 | AH4: Opening Stock | AJ4: =AD8 -> 165682950 | AM4: Opening Stock | AO4: =AI8 -> 183265550 | AR4: Opening Stock | AT4: =AN8 -> 170146900 | AW4: Purchases | AY4: 87160616
A5: Purchases | C5: 44129250 | E5: Purchases | G5: 67998481 | I5: Purchases | K5: 1.5343349e+08 | M5: Purchases | O5: 90532903 | Q5: Purchases | S5: 152256400 | U5: Purchases | W5: 54118402 | Y5: Purchases | AA5: 64288213 | AC5: Purchases | AE5: 118853610 | AH5: Purchases | AJ5: 153116585 | AM5: Purchases | AO5: 75093586 | AR5: Purchases | AT5: 185001035 | AW5: Accessories | AY5: 1001800
A6: Carriage Inward | C6: 508500 | E6: Carriage Inward | G6: 1421800 | I6: Carriage Inward | K6: 1350000 | M6: Carriage Inward | O6: 1870000 | Q6: Carriage Inward | S6: 1251000 | U6: Carriage Inward | W6: 335000 | Y6: Carriage Inward | AA6: 512500 | AC6: Carriage Inward | AE6: 1309800 | AH6: Carriage Inward | AJ6: 1714000 | AM6: Carriage Inward | AO6: 1640675 | AR6: Carriage Inward | AT6: 1496000 | AW6: Carriage Inward | AY6: 1167000
C7: =SUM(C4:C6) -> 146171110 | G7: =SUM(G4:G6) -> 176008781 | K7: =SUM(K4:K6) -> 2.5910994e+08 | O7: =SUM(O4:O6) -> 265149503 | S7: =SUM(S4:S6) -> 335612650 | W7: =SUM(W4:W6) -> 274245082 | AA7: =SUM(AA4:AA6) -> 263232873 | AE7: =SUM(AE4:AE6) -> 259881810 | AJ7: =SUM(AJ4:AJ6) -> 320513535 | AO7: =SUM(AO4:AO6) -> 259999811 | AT7: =SUM(AT4:AT6) -> 356643935 | AY7: =SUM(AY3:AY6) -> 267264116
A8: Closing Stock | B8: 106588500 | E8: Closing Stock | F8: 104326450 | I8: Closing Stock | J8: 172746600 | M8: Closing Stock | N8: 182105250 | Q8: Closing Stock | R8: =Stock!U144 -> 219791680 | U8: Closing Stock | V8: =Stock!AC145 -> 198432160 | Y8: Closing Stock | Z8: =Stock!AK135 -> 139718400 | AC8: Closing Stock | AD8: =Stock!AR145 -> 165682950 | AH8: Closing Stock | AI8: =Stock!AY142 -> 183265550 | AM8: Closing Stock | AN8: =Stock!BF136 -> 170146900 | AR8: Closing Stock | AS8: =Stock!BM114 -> 177934700 | AW8: Closing Stock | AX8: =Stock!BT112 -> 122651950
C9: =C7-B8 -> 39582610 | G9: =G7-F8 -> 71682331 | K9: =K7-J8 -> 86363337 | O9: =O7-N8 -> 83044253 | S9: =S7-R8 -> 115820970 | W9: =W7-V8 -> 75812922 | AA9: =AA7-Z8 -> 123514473 | AE9: =AE7-AD8 -> 94198860 | AJ9: =AJ7-AI8 -> 137247985 | AO9: =AO7-AN8 -> 89852911 | AT9: =AT7-AS8 -> 178709235 | AY9: =AY7-AX8 -> 144612166
A11: Factory Overhead | E11: Factory Overhead | I11: Factory Overhead | M11: Factory Overhead | Q11: Factory Overhead | U11: Factory Overhead | Y11: Factory Overhead | AC11: Factory Overhead | AH11: Factory Overhead | AM11: Factory Overhead | AR11: Factory Overhead | AW11: Factory Overhead
A12: Wages | B12: 253678.67 | E12: Wages | F12: 278680 | I12: Wages | J12: 281378.67 | M12: Wages | N12: 281378 | Q12: Wages | R12: 281378 | U12: Wages | V12: 281378 | Y12: Wages | Z12: 281378 | AC12: Wages | AD12: 281378 | AH12: Wages | AI12: 281378 | AM12: Wages | AN12: 281378 | AR12: Wages | AS12: 400000 | AW12: Wages | AX12: 420000
A13: Fuel & Lubricant | B13: 282500 | E13: Fuel & Lubricant | F13: 223000 | I13: Fuel & Lubricant | J13: 672000 | M13: Fuel & Lubricant | N13: 380500 | Q13: Fuel & Lubricant | R13: 384500 | U13: Fuel & Lubricant | V13: 433000 | Y13: Fuel & Lubricant | Z13: 480000 | AC13: Fuel & Lubricant | AD13: 647000 | AH13: Fuel & Lubricant | AI13: 560000 | AM13: Fuel & Lubricant | AN13: 400000 | AR13: Fuel & Lubricant | AS13: 515000 | AW13: Fuel & Lubricant | AX13: 555000
A14: Electricity Bill | B14: 20000 | E14: Electricity Bill | F14: 12500 | I14: Electricity Bill | J14: 15500 | M14: Electricity Bill | N14: 11000 | Q14: Electricity Bill | R14: 16000 | U14: Electricity Bill | V14: 62000 | Y14: Electricity Bill | Z14: 45000 | AC14: Electricity Bill | AD14: 5000 | AH14: Electricity Bill | AI14: 0 | AM14: Electricity Bill | AN14: 35000 | AR14: Electricity Bill | AS14: 0 | AW14: Electricity Bill | AX14: 0
A15: Maintainace | B15: 105500 | E15: Maintainace | F15: 302500 | I15: Maintainace | J15: 682600 | M15: Maintainace | N15: 684500 | Q15: Maintainace | R15: 1325650 | U15: Maintainace | V15: 659600 | Y15: Maintainace | Z15: 425000 | AC15: Maintainace | AD15: 612200 | AH15: Maintainace | AI15: 771576 | AM15: Maintainace | AN15: 514700 | AR15: Maintainace | AS15: 93000 | AW15: Maintainace | AX15: 937500
A16: Depreciation | B16: 110000 | E16: Depreciation | F16: 110000 | I16: Depreciation | J16: 110000 | M16: Depreciation | N16: 110000 | Q16: Depreciation | R16: 110000 | U16: Depreciation | V16: 110000 | Y16: Depreciation | Z16: 110000 | AC16: Depreciation | AD16: 110000 | AH16: Depreciation | AI16: 110000 | AM16: Depreciation | AN16: 110000 | AR16: Depreciation | AS16: 110000 | AW16: Depreciation | AX16: 110000
B17: =SUM(B12:B16) -> 771678.67 | F17: =SUM(F12:F16) -> 926680 | J17: =SUM(J12:J16) -> 1761478.7 | N17: =SUM(N12:N16) -> 1467378 | R17: =SUM(R12:R16) -> 2117528 | V17: =SUM(V12:V16) -> 1545978 | Z17: =SUM(Z12:Z16) -> 1341378 | AD17: =SUM(AD12:AD16) -> 1655578 | AI17: =SUM(AI12:AI16) -> 1722954 | AN17: =SUM(AN12:AN16) -> 1341078 | AS17: =SUM(AS12:AS16) -> 1118000 | AX17: =SUM(AX12:AX16) -> 2022500
C18: =C9+B17 -> 40354289 | G18: =G9+F17 -> 72609011 | K18: =K9+J17 -> 88124816 | O18: =O9+N17 -> 84511631 | S18: =S9+R17 -> 117938498 | W18: =W9+V17 -> 77358900 | AA18: =AA9+Z17 -> 124855851 | AE18: =AE9+AD17 -> 95854438 | AJ18: =AJ9+AI17 -> 138970939 | AO18: =AO9+AN17 -> 91193989 | AT18: =AT9+AS17 -> 179827235 | AY18: =AY9+AX17 -> 146634666
A20: Zarewa Aluminium And Plastics Ltd Kaduna | E20: Zarewa Aluminium And Plastics Ltd Kaduna | I20: Zarewa Aluminium And Plastics Ltd Kaduna | M20: Zarewa Aluminium And Plastics Ltd Kaduna | Q20: Zarewa Aluminium And Plastics Ltd Kaduna | U20: Zarewa Aluminium And Plastics Ltd Kaduna | Y20: Zarewa Aluminium And Plastics Ltd Kaduna | AC20: Zarewa Aluminium And Plastics Ltd Kaduna | AH20: Zarewa Aluminium And Plastics Ltd Kaduna | AM20: Zarewa Aluminium And Plastics Ltd Kaduna | AR20: Zarewa Aluminium And Plastics Ltd Kaduna | AW20: Zarewa Aluminium And Plastics Ltd Kaduna
A21: Profit and Lost Account for the month end Janaury | E21: Profit and Lost Account for the month end Febuary | I21: Profit and Lost Account for the month end Febuary | M21: Profit and Lost Account for the month end April | Q21: Profit and Lost Account for the month end May | U21: Profit and Lost Account for the month end June | Y21: Profit and Lost Account for the month end June | AC21: Profit and Lost Account for the month end August | AH21: Profit and Lost Account for the month end September | AM21: Profit and Lost Account for the month end Octorber | AR21: Profit and Lost Account for the month end Novemeber | AW21: Profit and Lost Account for the month end Decemebr
A22: Opening Stock | E22: Opening Stock | I22: Opening Stock | M22: Opening Stock | Q22: Opening Stock | U22: Opening Stock | Y22: Opening Stock | AC22: Opening Stock | AH22: Opening Stock | AM22: Opening Stock | AR22: Opening Stock | AW22: Opening Stock
A23: Sales | C23: 53323698 | E23: Sales | G23: 104795105 | I23: Sales | K23: 1.236522e+08 | M23: Sales | O23: 95528700 | Q23: Sales | S23: 163001075 | U23: Sales | W23: 84341891 | Y23: Sales | AA23: 152000000 | AC23: Sales | AE23: 130134588 | AH23: Sales | AJ23: 157461273 | AM23: Sales | AO23: 102424103 | AR23: Sales | AT23: 231774332 | AW23: Sales | AY23: 172755778
A24: Refund | B24: 4697544 | E24: Refund | F24: 7973518 | I24: Refund | J24: 11245242 | M24: Refund | N24: 8153703 | Q24: Refund | R24: 6426503 | U24: Refund | V24: 10779777 | Y24: Refund | Z24: 15848223 | AC24: Refund | AD24: 18137530 | AH24: Refund | AI24: 17842400 | AM24: Refund | AN24: 12640800 | AR24: Refund | AS24: 33183934 | AW24: Refund | AX24: 23930230
A25: Net Sales | C25: =C23-B24 -> 48626154 | E25: Net Sales | G25: =G23-F24 -> 96821587 | I25: Net Sales | K25: =K23-J24 -> 1.1240695e+08 | M25: Net Sales | O25: =O23-N24 -> 87374997 | Q25: Net Sales | S25: =S23-R24 -> 156574572 | U25: Net Sales | W25: =W23-V24 -> 73562114 | Y25: Net Sales | AA25: =AA23-Z24 -> 136151777 | AC25: Net Sales | AE25: =AE23-AD24 -> 111997058 | AH25: Net Sales | AJ25: =AJ23-AI24 -> 139618873 | AM25: Net Sales | AO25: =AO23-AN24 -> 89783303 | AR25: Net Sales | AT25: =AT23-AS24 -> 198590398 | AW25: Net Sales | AY25: =AY23-AX24 -> 148825548
A26: Production Cost | B26: =C18 -> 40354289 | E26: Production Cost | F26: =G18 -> 72609011 | I26: Production Cost | J26: =K18 -> 88124816 | M26: Production Cost | N26: =O18 -> 84511631 | Q26: Production Cost | R26: =S18 -> 117938498 | U26: Production Cost | V26: =W18 -> 77358900 | Y26: Production Cost | Z26: =AA18 -> 124855851 | AC26: Production Cost | AD26: =AE18 -> 95854438 | AH26: Production Cost | AI26: =AJ18 -> 138970939 | AM26: Production Cost | AN26: =AO18 -> 91193989 | AR26: Production Cost | AS26: =AT18 -> 179827235 | AW26: Production Cost | AX26: =AY18 -> 146634666
A27: Closing Stock | B27: 0 | E27: Closing Stock | F27: 0 | I27: Closing Stock | J27: 0 | M27: Closing Stock | N27: 0 | Q27: Closing Stock | R27: 0 | U27: Closing Stock | V27: 0 | Y27: Closing Stock | Z27: 0 | AC27: Closing Stock | AD27: 0 | AH27: Closing Stock | AI27: 0 | AM27: Closing Stock | AN27: 0 | AR27: Closing Stock | AS27: 0 | AW27: Closing Stock | AX27: 0
B28: =SUM(B26:B27) -> 40354289 | F28: =SUM(F26:F27) -> 72609011 | J28: =SUM(J26:J27) -> 88124816 | N28: =SUM(N26:N27) -> 84511631 | R28: =SUM(R26:R27) -> 117938498 | V28: =SUM(V26:V27) -> 77358900 | Z28: =SUM(Z26:Z27) -> 124855851 | AD28: =SUM(AD26:AD27) -> 95854438 | AI28: =SUM(AI26:AI27) -> 138970939 | AN28: =SUM(AN26:AN27) -> 91193989 | AS28: =SUM(AS26:AS27) -> 179827235 | AX28: =SUM(AX26:AX27) -> 146634666
A29: Gross Profit | C29: =C25-B28 -> 8271865.3 | E29: Gross Profit | G29: =G25-F28 -> 24212576 | I29: Gross Profit | K29: =K25-J28 -> 24282138 | M29: Gross Profit | O29: =O25-N28 -> 2863366 | Q29: Gross Profit | S29: =S25-R28 -> 38636074 | U29: Gross Profit | W29: =W25-V28 -> -3796786 | Y29: Gross Profit | AA29: =AA25-Z28 -> 11295926 | AC29: Gross Profit | AE29: =AE25-AD28 -> 16142620 | AH29: Gross Profit | AJ29: =AJ25-AI28 -> 647934 | AM29: Gross Profit | AO29: =AO25-AN28 -> -1410686 | AR29: Gross Profit | AT29: =AT25-AS28 -> 18763163 | AW29: Gross Profit | AY29: =AY25-AX28 -> 2190882
A31: Admin Expenses | E31: Admin Expenses | I31: Admin Expenses | M31: Admin Expenses | Q31: Admin Expenses | U31: Admin Expenses | Y31: Admin Expenses | AC31: Admin Expenses | AH31: Admin Expenses | AM31: Admin Expenses | AR31: Admin Expenses | AW31: Admin Expenses
A32: Admin exp | B32: 0 | E32: Admin exp | F32: 0 | I32: Admin exp | J32: 0 | M32: Admin exp | N32: 70000 | Q32: Admin exp | R32: 75000 | U32: Admin exp | V32: 82000 | Y32: Admin exp | Z32: 70000 | AC32: Admin exp | AD32: 100000 | AH32: Admin exp | AI32: 74000 | AM32: Admin exp | AN32: 10000 | AR32: Admin exp | AS32: 15000 | AW32: Admin exp | AX32: 95000
A33: Admin Salary | B33: 377465.6 | E33: Admin Salary | F33: 337465.6 | I33: Admin Salary | J33: 398065.6 | M33: Admin Salary | N33: 398000 | Q33: Admin Salary | R33: 398000 | U33: Admin Salary | V33: 398000 | Y33: Admin Salary | Z33: 398000 | AC33: Admin Salary | AD33: 398000 | AH33: Admin Salary | AI33: 398000 | AM33: Admin Salary | AN33: 410000 | AR33: Admin Salary | AS33: 750000 | AW33: Admin Salary | AX33: 750000
A34: Bank Charge | B34: 5678.18 | E34: Bank Charge | F34: 0 | I34: Bank Charge | J34: 35475 | M34: Bank Charge | N34: 0 | Q34: Bank Charge | R34: 22827 | U34: Bank Charge | Y34: Bank Charge | AC34: Bank Charge | AH34: Bank Charge | AM34: Bank Charge | AR34: Bank Charge | AS34: 4312 | AW34: Bank Charge | AX34: 5331.2
A35: Office Expenses | B35: 56000 | E35: Office Expenses | F35: 99000 | I35: Office Expenses | J35: 74150 | M35: Office Expenses | N35: 55500 | Q35: Office Expenses | R35: 201000 | U35: Office Expenses | V35: 88500 | Y35: Office Expenses | Z35: 205000 | AC35: Office Expenses | AD35: 58000 | AH35: Office Expenses | AI35: 59000 | AM35: Office Expenses | AN35: 125654 | AR35: Office Expenses | AS35: 107000 | AW35: Office Expenses | AX35: 377200
A36: Professional Fee | B36: 361000 | E36: Professional Fee | F36: 50000 | I36: Professional Fee | J36: 0 | M36: Professional Fee | N36: 0 | Q36: Professional Fee | R36: 0 | U36: Professional Fee | V36: 150000 | Y36: Professional Fee | Z36: 150000 | AC36: Professional Fee | AD36: 167000 | AH36: Professional Fee | AM36: Professional Fee | AR36: Professional Fee | AS36: 150000 | AW36: Professional Fee | AX36: 0
A37: Tax | B37: 0 | E37: Tax | F37: 872000 | I37: Tax | J37: 0 | M37: Tax | N37: 366205 | Q37: Tax | R37: 10000 | U37: Tax | V37: 52500 | Y37: Tax | Z37: 593000 | AC37: Tax | AD37: 0 | AH37: Tax | AI37: 425000 | AM37: Tax | AN37: 650000 | AR37: Tax | AS37: 880841 | AW37: Tax | AX37: 377186
A38: Pension | B38: 53900 | E38: Pension | F38: 0 | I38: Pension | J38: 0 | M38: Pension | N38: 0 | Q38: Pension | R38: 0 | U38: Pension | Y38: Pension | AC38: Pension | AH38: Pension | AM38: Pension | AN38: 1000000 | AR38: Pension | AW38: Pension | AX38: 0
A39: Security | B39: 0 | E39: Security | F39: 25000 | I39: Security | J39: 25000 | M39: Security | N39: 0 | Q39: Security | R39: 0 | U39: Security | Y39: Security | AC39: Security | AH39: Security | AM39: Security | AR39: Security | AS39: 30000 | AW39: Security | AX39: 210000
A40: Intrest | B40: 0 | E40: Intrest | F40: 0 | I40: Intrest | J40: 0 | M40: Intrest | N40: 0 | Q40: Intrest | R40: 0 | U40: Intrest | Y40: Intrest | AC40: Intrest | AH40: Intrest | AM40: Intrest | AR40: Intrest | AW40: Intrest
A41: Welfare | B41: 182800 | E41: Welfare | F41: 125000 | I41: Welfare | J41: 887000 | M41: Welfare | N41: 0 | Q41: Welfare | R41: 0 | U41: Welfare | Y41: Welfare | AC41: Welfare | AH41: Welfare | AM41: Welfare | AR41: Welfare | AW41: Welfare | AX41: 300000
A42: Zakat & Sallah | B42: 0 | E42: Zakat & Sallah | F42: 0 | I42: Zakat & Sallah | J42: 541527 | M42: Zakat & Sallah | N42: 120000 | Q42: Zakat & Sallah | R42: 0 | U42: Zakat & Sallah | V42: 400000 | Y42: Zakat & Sallah | Z42: 0 | AC42: Zakat & Sallah | AD42: 0 | AH42: Zakat & Sallah | AI42: 0 | AM42: Zakat & Sallah | AN42: 0 | AR42: Zakat & Sallah | AW42: Zakat & Sallah
B43: =SUM(B32:B42) -> 1036843.8 | F43: =SUM(F32:F42) -> 1508465.6 | J43: =SUM(J32:J42) -> 1961217.6 | N43: =SUM(N32:N42) -> 1009705 | R43: =SUM(R32:R42) -> 706827 | V43: =SUM(V32:V42) -> 1171000 | Z43: =SUM(Z32:Z42) -> 1416000 | AD43: =SUM(AD32:AD42) -> 723000 | AI43: =SUM(AI32:AI42) -> 956000 | AN43: =SUM(AN32:AN42) -> 2195654 | AS43: =SUM(AS32:AS42) -> 1937153 | AX43: =SUM(AX32:AX42) -> 2114717.2
...

Sheet 2025
A2: Zarewa Aluminium And Plastics Ltd Kaduna | E2: Zarewa Aluminium And Plastics Ltd Kaduna | I2: Zarewa Aluminium And Plastics Ltd Kaduna | M2: Zarewa Aluminium And Plastics Ltd Kaduna | Q2: Zarewa Aluminium And Plastics Ltd Kaduna | U2: Zarewa Aluminium And Plastics Ltd Kaduna | Y2: Zarewa Aluminium And Plastics Ltd Kaduna | AC2: Zarewa Aluminium And Plastics Ltd Kaduna | AG2: Zarewa Aluminium And Plastics Ltd Kaduna | AK2: Zarewa Aluminium And Plastics Ltd Kaduna | AO2: Zarewa Aluminium And Plastics Ltd Kaduna | AS2: Zarewa Aluminium And Plastics Ltd Kaduna
A3: Production Account for the month end january | E3: Production Account for the month end Febaury | I3: Production Account for the month end March | M3: Production Account for the month end April | Q3: Production Account for the month end May | U3: Production Account for the month end june | Y3: Production Account for the month end july | AC3: Production Account for the month end August | AG3: Production Account for the month end September | AK3: Production Account for the month end October | AO3: Production Account for the month end November | AS3: Production Account for the month end December
A4: Opening Stock | C4: ='2024'!AX8 -> 122651950 | E4: Opening Stock | G4: =B9 -> 131675600 | I4: Opening Stock | K4: =F9 -> 139361880 | M4: Opening Stock | O4: =J9 -> 111633000 | Q4: Opening Stock | S4: =N9 -> 86993000 | U4: Opening Stock | W4: =R9 -> 134491100 | Y4: Opening Stock | AA4: =V9 -> 105456800 | AC4: Opening Stock | AE4: =Z9 -> 134156060 | AG4: Opening Stock | AI4: =AD9 -> 200668660 | AK4: Opening Stock | AM4: =AH9 -> 162596190 | AO4: Opening Stock | AQ4: =AL9 -> 162871360 | AS4: Opening Stock | AU4: =AP9 -> 179392750
A5: Purchases | C5: 124853410 | E5: Purchases | G5: 101428439 | I5: Purchases | K5: 57596660 | M5: Purchases | O5: 128120230 | Q5: Purchases | S5: 179354850 | U5: Purchases | W5: 172892658 | Y5: Purchases | AA5: 194843909 | AC5: Purchases | AE5: 269287184 | AG5: Purchases | AI5: 122939000 | AK5: Purchases | AM5: 124487050 | AO5: Purchases | AQ5: 206010999 | AS5: Purchases | AU5: 63804275
A6: Accessories | C6: 1532000 | E6: Accessories | G6: 691500 | I6: Accessories | K6: 1027500 | M6: Accessories | O6: 680600 | Q6: Accessories | S6: 1339620 | U6: Accessories | W6: 1299200 | Y6: Accessories | AA6: 2228500 | AC6: Accessories | AE6: 3519000 | AG6: Accessories | AI6: 7368020 | AK6: Accessories | AM6: 1883020 | AO6: Accessories | AQ6: 1824500 | AS6: Accessories | AU6: 677220
A7: Carriage Inward | C7: 1560000 | E7: Carriage Inward | G7: 1140000 | I7: Carriage Inward | K7: 609500 | M7: Carriage Inward | O7: 1755000 | Q7: Carriage Inward | S7: 1115000 | U7: Carriage Inward | W7: 1744000 | Y7: Carriage Inward | AA7: 3252000 | AC7: Carriage Inward | AE7: 3857000 | AG7: Carriage Inward | AI7: 2910500 | AK7: Carriage Inward | AM7: 1850500 | AO7: Carriage Inward | AQ7: 4226500 | AS7: Carriage Inward | AU7: 425000
C8: =SUM(C4:C7) -> 250597360 | G8: =SUM(G4:G7) -> 234935539 | K8: =SUM(K4:K7) -> 198595540 | O8: =SUM(O4:O7) -> 242188830 | S8: =SUM(S4:S7) -> 268802470 | W8: =SUM(W4:W7) -> 310426958 | AA8: =SUM(AA4:AA7) -> 305781209 | AE8: =SUM(AE4:AE7) -> 410819244 | AI8: =SUM(AI4:AI7) -> 333886180 | AM8: =SUM(AM4:AM7) -> 290816760 | AQ8: =SUM(AQ4:AQ7) -> 374933359 | AU8: =SUM(AU4:AU7) -> 244299245
A9: Closing Stock | B9: 131675600 | E9: Closing Stock | F9: 139361880 | I9: Closing Stock | J9: 111633000 | M9: Closing Stock | N9: =Stock!CA102 -> 86993000 | Q9: Closing Stock | R9: =Stock!CH103 -> 134491100 | U9: Closing Stock | V9: =Stock!CO98 -> 105456800 | Y9: Closing Stock | Z9: =Stock!CV110 -> 134156060 | AC9: Closing Stock | AD9: =Stock!DC123 -> 200668660 | AG9: Closing Stock | AH9: =Stock!DJ128 -> 162596190 | AK9: Closing Stock | AL9: =Stock!DQ128 -> 162871360 | AO9: Closing Stock | AP9: =Stock!DX148 -> 179392750 | AS9: Closing Stock | AT9: =Stock!EE136 -> 152704600
C10: =C8-B9 -> 118921760 | G10: =G8-F9 -> 95573659 | K10: =K8-J9 -> 86962540 | O10: =O8-N9 -> 155195830 | S10: =S8-R9 -> 134311370 | W10: =W8-V9 -> 204970158 | AA10: =AA8-Z9 -> 171625149 | AE10: =AE8-AD9 -> 210150584 | AI10: =AI8-AH9 -> 171289990 | AM10: =AM8-AL9 -> 127945400 | AQ10: =AQ8-AP9 -> 195540609 | AU10: =AU8-AT9 -> 91594645
A12: Factory Overhead | E12: Factory Overhead | I12: Factory Overhead | M12: Factory Overhead | Q12: Factory Overhead | U12: Factory Overhead | Y12: Factory Overhead | AC12: Factory Overhead | AG12: Factory Overhead | AK12: Factory Overhead | AO12: Factory Overhead | AS12: Factory Overhead
A13: Wages | B13: 420000 | E13: Wages | F13: 420000 | I13: Wages | J13: 420000 | M13: Wages | N13: 450000 | Q13: Wages | R13: 450000 | U13: Wages | V13: 450000 | Y13: Wages | Z13: 450000 | AC13: Wages | AD13: 450000 | AG13: Wages | AH13: 450000 | AK13: Wages | AL13: 450000 | AO13: Wages | AP13: 450000 | AS13: Wages | AT13: 450000
A14: Fuel & Lubricant | B14: 655811 | E14: Fuel & Lubricant | F14: 575000 | I14: Fuel & Lubricant | J14: 330000 | M14: Fuel & Lubricant | N14: 274420 | Q14: Fuel & Lubricant | R14: 1105000 | U14: Fuel & Lubricant | V14: 1006000 | Y14: Fuel & Lubricant | Z14: 917500 | AC14: Fuel & Lubricant | AD14: 749000 | AG14: Fuel & Lubricant | AH14: 639000 | AK14: Fuel & Lubricant | AL14: 260000 | AO14: Fuel & Lubricant | AP14: 595000 | AS14: Fuel & Lubricant | AT14: 507695
A15: Electricity Bill | B15: 0 | E15: Electricity Bill | F15: 0 | I15: Electricity Bill | J15: 0 | M15: Electricity Bill | N15: 0 | Q15: Electricity Bill | R15: 0 | U15: Electricity Bill | Y15: Electricity Bill | AC15: Electricity Bill | AG15: Electricity Bill | AK15: Outside currugation | AL15: 529120 | AO15: Outside currugation | AP15: 171000 | AS15: Outside currugation
A16: Maintainace | B16: 377800 | E16: Maintainace | F16: 981500 | I16: Maintainace | J16: 48000 | M16: Maintainace | N16: 370000 | Q16: Maintainace | R16: 1058000 | U16: Maintainace | V16: 1378000 | Y16: Maintainace | Z16: 617000 | AC16: Maintainace | AD16: 309100 | AG16: Maintainace | AH16: 129500 | AK16: Maintainace | AL16: 473000 | AO16: Maintainace | AP16: 300900 | AS16: Maintainace | AT16: 465300
A17: Depreciation | B17: 110000 | E17: Depreciation | F17: 110000 | I17: Depreciation | J17: 110000 | M17: Depreciation | N17: 110000 | Q17: Depreciation | R17: 110000 | U17: Depreciation | V17: 110000 | Y17: Depreciation | Z17: 110000 | AC17: Depreciation | AD17: 110000 | AG17: Depreciation | AH17: 110000 | AK17: Depreciation | AL17: 110000 | AO17: Depreciation | AP17: 110000 | AS17: Depreciation | AT17: 110000
B18: =SUM(B13:B17) -> 1563611 | F18: =SUM(F13:F17) -> 2086500 | J18: =SUM(J13:J17) -> 908000 | N18: =SUM(N13:N17) -> 1204420 | R18: =SUM(R13:R17) -> 2723000 | V18: =SUM(V13:V17) -> 2944000 | Z18: =SUM(Z13:Z17) -> 2094500 | AD18: =SUM(AD13:AD17) -> 1618100 | AH18: =SUM(AH13:AH17) -> 1328500 | AL18: =SUM(AL13:AL17) -> 1822120 | AP18: =SUM(AP13:AP17) -> 1626900 | AT18: =SUM(AT13:AT17) -> 1532995
C19: =C10+B18 -> 120485371 | G19: =G10+F18 -> 97660159 | K19: =K10+J18 -> 87870540 | O19: =O10+N18 -> 156400250 | S19: =S10+R18 -> 137034370 | W19: =W10+V18 -> 207914158 | AA19: =AA10+Z18 -> 173719649 | AE19: =AE10+AD18 -> 211768684 | AI19: =AI10+AH18 -> 172618490 | AM19: =AM10+AL18 -> 129767520 | AQ19: =AQ10+AP18 -> 197167509 | AU19: =AU10+AT18 -> 93127640
A21: Zarewa Aluminium And Plastics Ltd Kaduna | E21: Zarewa Aluminium And Plastics Ltd Kaduna | I21: Zarewa Aluminium And Plastics Ltd Kaduna | M21: Zarewa Aluminium And Plastics Ltd Kaduna | Q21: Zarewa Aluminium And Plastics Ltd Kaduna | U21: Zarewa Aluminium And Plastics Ltd Kaduna | Y21: Zarewa Aluminium And Plastics Ltd Kaduna | AC21: Zarewa Aluminium And Plastics Ltd Kaduna | AG21: Zarewa Aluminium And Plastics Ltd Kaduna | AK21: Zarewa Aluminium And Plastics Ltd Kaduna | AO21: Zarewa Aluminium And Plastics Ltd Kaduna | AS21: Zarewa Aluminium And Plastics Ltd Kaduna
A22: Profit and Lost Account for the month end January | E22: Profit and Lost Account for the month end Feb | I22: Profit and Lost Account for the month end Feb | M22: Profit and Lost Account for the month end may | Q22: Profit and Lost Account for the month end may | U22: Profit and Lost Account for the month end june | Y22: Profit and Lost Account for the month end july | AC22: Profit and Lost Account for the month end Agust | AG22: Profit and Lost Account for the month end September | AK22: Profit and Lost Account for the month end October | AO22: Profit and Lost Account for the month end November | AS22: Profit and Lost Account for the month end November
A23: Opening Stock | E23: Opening Stock | I23: Opening Stock | M23: Opening Stock | Q23: Opening Stock | U23: Opening Stock | Y23: Opening Stock | AC23: Opening Stock | AG23: Opening Stock | AK23: Opening Stock | AO23: Opening Stock | AS23: Opening Stock
A24: Sales | C24: 135829763 | E24: Sales | G24: 104097648 | I24: Sales | K24: 101071816 | M24: Sales | O24: 175194444 | Q24: Sales | S24: 157781840 | U24: Sales | W24: 268750154 | Y24: Sales | AA24: 204269779 | AC24: Sales | AE24: 273198040 | AG24: Sales | AI24: 197873718 | AK24: Sales | AM24: 174627389 | AO24: Sales | AQ24: 230293875 | AS24: Sales | AU24: 127427926
A25: Refund | B25: 14490272 | E25: Refund | F25: 7814104 | I25: Refund | J25: 8969253 | M25: Refund | N25: 12077151 | Q25: Refund | R25: 17065392 | U25: Refund | V25: 48492193 | Y25: Refund | Z25: 19277043 | AC25: Refund | AD25: 31949300 | AG25: Refund | AH25: 20496111 | AK25: Refund | AL25: 19326225 | AO25: Refund | AP25: 27219479 | AS25: Refund | AT25: 21337575
A26: Net Sales | C26: =C24-B25 -> 121339491 | E26: Net Sales | G26: =G24-F25 -> 96283544 | I26: Net Sales | K26: =K24-J25 -> 92102563 | M26: Net Sales | O26: =O24-N25 -> 163117293 | Q26: Net Sales | S26: =S24-R25 -> 140716448 | U26: Net Sales | W26: =W24-V25 -> 220257961 | Y26: Net Sales | AA26: =AA24-Z25 -> 184992736 | AC26: Net Sales | AE26: =AE24-AD25 -> 241248740 | AG26: Net Sales | AI26: =AI24-AH25 -> 177377607 | AK26: Net Sales | AM26: =AM24-AL25 -> 155301164 | AO26: Net Sales | AQ26: =AQ24-AP25 -> 203074396 | AS26: Net Sales | AU26: =AU24-AT25 -> 106090351
A27: Production Cost | B27: =C19 -> 120485371 | E27: Production Cost | F27: =G19 -> 97660159 | I27: Production Cost | J27: =K19 -> 87870540 | M27: Production Cost | N27: =O19 -> 156400250 | Q27: Production Cost | R27: =S19 -> 137034370 | U27: Production Cost | V27: =W19 -> 207914158 | Y27: Production Cost | Z27: =AA19 -> 173719649 | AC27: Production Cost | AD27: =AE19 -> 211768684 | AG27: Production Cost | AH27: =AI19 -> 172618490 | AK27: Production Cost | AL27: =AM19 -> 129767520 | AO27: Production Cost | AP27: =AQ19 -> 197167509 | AS27: Production Cost | AT27: =AU19 -> 93127640
A28: Closing Stock | B28: 0 | E28: Closing Stock | F28: 0 | I28: Closing Stock | J28: 0 | M28: Closing Stock | N28: 0 | Q28: Closing Stock | R28: 0 | U28: Closing Stock | V28: 0 | Y28: Closing Stock | Z28: 0 | AC28: Closing Stock | AD28: 0 | AG28: Closing Stock | AH28: 0 | AK28: Closing Stock | AL28: 0 | AO28: Closing Stock | AP28: 0 | AS28: Closing Stock | AT28: 0
B29: =SUM(B27:B28) -> 120485371 | F29: =SUM(F27:F28) -> 97660159 | J29: =SUM(J27:J28) -> 87870540 | N29: =SUM(N27:N28) -> 156400250 | R29: =SUM(R27:R28) -> 137034370 | V29: =SUM(V27:V28) -> 207914158 | Z29: =SUM(Z27:Z28) -> 173719649 | AD29: =SUM(AD27:AD28) -> 211768684 | AH29: =SUM(AH27:AH28) -> 172618490 | AL29: =SUM(AL27:AL28) -> 129767520 | AP29: =SUM(AP27:AP28) -> 197167509 | AT29: =SUM(AT27:AT28) -> 93127640
A30: Gross Profit | C30: =C26-B29 -> 854120 | E30: Gross Profit | G30: =G26-F29 -> -1376615 | I30: Gross Profit | K30: =K26-J29 -> 4232023 | M30: Gross Profit | O30: =O26-N29 -> 6717043 | Q30: Gross Profit | S30: =S26-R29 -> 3682078 | U30: Gross Profit | W30: =W26-V29 -> 12343803 | Y30: Gross Profit | AA30: =AA26-Z29 -> 11273087 | AC30: Gross Profit | AE30: =AE26-AD29 -> 29480056 | AG30: Gross Profit | AI30: =AI26-AH29 -> 4759117 | AK30: Gross Profit | AM30: =AM26-AL29 -> 25533644 | AO30: Gross Profit | AQ30: =AQ26-AP29 -> 5906887 | AS30: Gross Profit | AU30: =AU26-AT29 -> 12962711
A32: Admin Expenses | E32: Admin Expenses | I32: Admin Expenses | M32: Admin Expenses | Q32: Admin Expenses | U32: Admin Expenses | Y32: Admin Expenses | AC32: Admin Expenses | AG32: Admin Expenses | AK32: Admin Expenses | AO32: Admin Expenses | AS32: Admin Expenses
A33: Admin exp | B33: 20000 | E33: Admin exp | F33: 30000 | I33: Admin exp | J33: 0 | M33: Admin exp | N33: 202000 | Q33: Admin exp | R33: 120000 | U33: Admin exp | V33: 122500 | Y33: Admin exp | Z33: 325000 | AC33: Admin exp | AD33: 111000 | AG33: Admin exp | AH33: 275000 | AK33: Admin exp | AL33: 110400 | AO33: Admin exp | AP33: 105000 | AS33: Admin exp | AT33: 115000
A34: Admin Salary | B34: 750000 | E34: Admin Salary | F34: 750000 | I34: Admin Salary | J34: 750000 | M34: Admin Salary | N34: 550000 | Q34: Admin Salary | R34: 750000 | U34: Admin Salary | V34: 750000 | Y34: Admin Salary | Z34: 750000 | AC34: Admin Salary | AD34: 750000 | AG34: Admin Salary | AH34: 750000 | AK34: Admin Salary | AL34: 750000 | AO34: Admin Salary | AP34: 750000 | AS34: Admin Salary | AT34: 1150000
A35: Bank Charge | B35: 0 | E35: Bank Charge | F35: 8265.85 | I35: Bank Charge | J35: 10510 | M35: Bank Charge | N35: 0 | Q35: Bank Charge | R35: 5636 | U35: Bank Charge | V35: 7777 | Y35: Bank Charge | Z35: 7900 | AC35: Bank Charge | AD35: 5393.25 | AG35: Bank Charge | AH35: 187318.42 | AK35: Bank Charge | AL35: 51638.1 | AO35: Bank Charge | AP35: 87879.75 | AS35: Bank Charge | AT35: 6087
A36: Office Expenses | B36: 126800 | E36: Office Expenses | F36: 39600 | I36: Office Expenses | J36: 140000 | M36: Office Expenses | N36: 74000 | Q36: Office Expenses | R36: 16000 | U36: Office Expenses | V36: 53200 | Y36: Office Expenses | Z36: 29020 | AC36: Office Expenses | AD36: 622700 | AG36: Office Expenses | AH36: 197400 | AK36: Office Expenses | AL36: 1585400 | AO36: Office Expenses | AP36: 1041100 | AS36: Office Expenses | AT36: 686400
A37: Professional Fee | B37: 0 | E37: Professional Fee | F37: 0 | I37: Professional Fee | J37: 0 | M37: Professional Fee | N37: 0 | Q37: Professional Fee | R37: 150000 | U37: Professional Fee | Y37: Professional Fee | AC37: Professional Fee | AG37: Professional Fee | AK37: Professional Fee | AL37: 25000 | AO37: Professional Fee | AP37: 150000 | AS37: Professional Fee | AT37: 495000
A38: Tax | B38: 538800 | E38: Tax | F38: 194000 | I38: Tax | J38: 175000 | M38: Tax | N38: 745000 | Q38: Tax | R38: 70000 | U38: Tax | Y38: Tax | Z38: 666590 | AC38: Tax | AD38: 1348037 | AG38: Tax | AK38: Tax | AO38: Tax | AS38: Tax
A39: Pension | B39: 0 | E39: Pension | F39: 0 | I39: Pension | J39: 0 | M39: Pension | N39: 0 | Q39: Pension | R39: 0 | U39: Pension | Y39: Pension | AC39: Pension | AG39: Pension | AK39: Pension | AO39: Pension | AS39: Pension
A40: Security | B40: 135000 | E40: Security | F40: 115000 | I40: Security | J40: 115000 | M40: Security | N40: 131000 | Q40: Security | R40: 115000 | U40: Security | V40: 107500 | Y40: Security | Z40: 100000 | AC40: Security | AD40: 150000 | AG40: Security | AH40: 100000 | AK40: Security | AL40: 100000 | AO40: Security | AP40: 100000 | AS40: Security | AT40: 100000
A41: Intrest | E41: Intrest | I41: Intrest | M41: Intrest | Q41: Intrest | U41: Intrest | Y41: Intrest | AC41: Intrest | AG41: Intrest | AK41: Intrest | AO41: Intrest | AS41: Intrest
A42: Welfare | B42: 0 | E42: Welfare | F42: 0 | I42: Welfare | J42: 0 | M42: Welfare | N42: 0 | Q42: Welfare | R42: 0 | U42: Welfare | Y42: Welfare | AC42: Welfare | AG42: Welfare | AK42: Welfare | AO42: Welfare | AS42: Welfare
A43: Zakat & Sallah | E43: Zakat & Sallah | F43: 1000000 | I43: Zakat & Sallah | J43: 2150000 | M43: Zakat & Sallah | N43: 0 | Q43: Zakat & Sallah | R43: 800000 | U43: Zakat & Sallah | Y43: Zakat & Sallah | AC43: Zakat & Sallah | AG43: Zakat & Sallah | AK43: Zakat & Sallah | AO43: Zakat & Sallah | AS43: Zakat & Sallah
B44: =SUM(B33:B43) -> 1570600 | F44: =SUM(F33:F43) -> 2136865.9 | J44: =SUM(J33:J43) -> 3340510 | N44: =SUM(N33:N43) -> 1702000 | R44: =SUM(R33:R43) -> 2026636 | V44: =SUM(V33:V43) -> 1040977 | Z44: =SUM(Z33:Z43) -> 1878510 | AD44: =SUM(AD33:AD43) -> 2987130.2 | AH44: =SUM(AH33:AH43) -> 1509718.4 | AL44: =SUM(AL33:AL43) -> 2622438.1 | AP44: =SUM(AP33:AP43) -> 2233979.8 | AT44: =SUM(AT33:AT43) -> 2552487
...

Sheet Sheet1
C1: Summary Of Kaduna Asset for a year
D2: Overhead | E2: External Expenses | F2: Profit | G2: Asset
B3: 2024 | C3: Aug | D3: 1655578 | E3: 2348000 | F3: 12571620 | G3: 212204601
C4: Sep | D4: 1722954 | E4: 1174500 | F4: -1982566 | G4: 226090314
C5: oct | D5: 1341078 | E5: 1396000 | F5: -5502340 | G5: 191058519
C6: nov | D6: 1118000 | E6: 1615000 | F6: 14511010 | G6: 1.9685628e+08
C7: dec | D7: 2022500 | E7: 678000 | F7: -601835.2 | G7: 1.9531822e+08
B8: 2025 | C8: jan | D8: 1563611 | E8: 303000 | F8: -1019480 | G8: 191783632
C9: feb | D9: 2086500 | E9: 3375000 | F9: -6888480.8 | G9: 187529062
C10: mar | D10: 908000 | E10: 2385000 | F10: -1493487 | G10: 151978382
C11: apr | D11: 1204420 | E11: 2850000 | F11: 2165043 | G11: 150339182
C12: may | D12: 2723000 | E12: 364000 | F12: 1291442 | G12: 156715644
C13: jun | D13: 2944000 | E13: 1564350 | F13: 9738476 | G13: 1.7057536e+08
C14: jul | D14: 2094500 | E14: 752000 | F14: 8642577 | G14: 168642330
C15: aug | D15: 1618100 | E15: 3183000 | F15: 23309926 | G15: 217732991
B16: Total | D16: =SUM(D3:D15) -> 23002241 | E16: =SUM(E3:E15) -> 21987850 | F16: =SUM(F3:F15) -> 54741905 | G16: 217732991

Sheet Stock
B1: END OF THE MONTH OF SEPTEMBER 2023 | H1: END OF THE MONTH OF APRIL STOCK 2024 | P1: END OF THE MONTH OF MAY 2024 | X1: END OF THE MONTH OF JUNE 2024 | AF1: END OF THE MONTH OF JUly 2024 | AM1: END OF THE MONTH OF AUGUST | AT1: END OF THE MONTH OF SEPTEMBER 2024 | BA1: END OF THE MONTH OF OCTOBER 2024 | BH1: END OF THE MONTH OF November 2024 | BO1: END OF THE MONTH OF DECEMBER2024 | BV1: Stock for the end of the month of April 2025 | CC1: Stock for the end of the month of May 2025 | CJ1: Stock for the end of the month of June 2025 | CQ1: Stock for the end of the month of July 2025 | CX1: Stock for the end of the month of August 2025 | DD1: Stock for the end of the month of September 2025 | DL1: Stock for the end of the month of October 2025 | DS1: Stock for the end of the month of November 2025 | DZ1: Stock for the end of the month of December 2025
B2: S/N | C2: CLOUR | D2: COIL NO | E2: KG | F2: REMARK | H2: S/N | I2: COLOUR | J2: COIL NO | K2: KG | L2: REMARK | P2: S/N | Q2: COLOUR | R2: COIL NO | S2: KG | T2: REMARK | X2: S/N | Y2: COLOUR | Z2: COIL NO | AA2: KG | AB2: REMARK | AF2: S/N | AG2: COLOUR | AH2: COIL NO | AI2: KG | AJ2: REMARK | AM2: S/N | AN2: COLOUR | AO2: COIL NO | AP2: KG | AQ2: REMARK | AT2: S/N | AU2: COLOUR | AV2: COIL NO | AW2: KG | AX2: REMARK | BA2: S/N | BB2: COLOUR | BC2: COIL NO | BD2: KG | BE2: REMARK | BH2: S/N | BI2: COLOUR | BJ2: COIL NO | BK2: KG | BL2: REMARK | BO2: S/N | BP2: COLOUR | BQ2: COIL NO | BR2: KG | BS2: REMARK | BV2: S/N | BW2: Colour | BX2: C/No | BY2: KG | BZ2: Remark | CC2: S/N | CD2: Colour | CE2: C/No | CF2: KG | CG2: Remark | CJ2: S/N | CK2: Colour | CL2: C/No | CM2: KG | CN2: Remark | CQ2: S/N | CR2: Colour | CS2: C/No | CT2: KG | CU2: Remark | CX2: S/N | CY2: Colour | CZ2: C/No | DA2: KG | DB2: Remark | DD2: S/N | DE2: COLOUR | DF2: C/No | DG2: KG | DH2: REMARK | DL2: S/N | DM2: Colour | DN2: C/N | DO2: KG | DP2: Remark | DS2: S/N | DT2: COLOUR | DU2: C/NO | DV2: KG | DZ2: S/N | EA2: COLOUR | EB2: C/NO | EC2: KG | ED2: REMARK
B3: 0.45 | H3: 0.45 | Q3: 0.45 | Y3: 0.45 | AG3: 0.45 | AM3: 0.45 | AT3: 0.45 | BA3: 0.45 | BH3: 0.45 | BO3: 0.45 | BV3: 0.45 | CC3: 0.45 | CJ3: 0.45 | CQ3: 0.45 | CX3: 0.45 | DD3: 0.45 | DL3: 0.45 | DS3: 0.55F | DZ3: 0.7
B4: 1 | C4: GB | D4: 1399 | E4: 1766 | H4: 1 | I4: IV | J4: 1257 | K4: 360 | P4: 1 | Q4: GB | R4: 1399 | S4: 1530 | X4: 1 | Y4: GB | Z4: 1399 | AA4: 1515 | AF4: 1 | AG4: GB | AH4: 1399 | AI4: 1445 | AM4: 1 | AN4: GB | AO4: 1399 | AP4: 1421 | AT4: 1 | AU4: IV | AV4: 1257 | AW4: 264 | BA4: 1 | BB4: IV | BC4: 1257 | BD4: 264 | BH4: 1 | BI4: IV | BJ4: 1257 | BK4: 264 | BO4: 1 | BP4: IV | BQ4: 1257 | BR4: 231 | BV4: 1 | BW4: IV | BX4: 1257 | BY4: 170 | CC4: 1 | CD4: IV | CE4: 1257 | CF4: 170 | CJ4: 1 | CK4: IV | CL4: 1257 | CM4: 156 | CQ4: 1 | CR4: GB | CS4: 1399 | CT4: 888 | CX4: 1 | CY4: GB | CZ4: 1399 | DA4: 862 | DD4: 1 | DE4: BG | DF4: 1435 | DG4: 68 | DL4: 1 | DM4: IV | DN4: 1257 | DO4: 84 | DS4: 1 | DT4: HMB | DU4: 1878 | DV4: 778 | DZ4: 1 | EA4: TCR | EB4: 1552 | EC4: 55
B5: 2 | C5: IV | D5: 1257 | E5: 745 | H5: 2 | I5: GB | J5: 1399 | K5: 1671 | P5: 2 | Q5: IV | R5: 1257 | S5: 314 | X5: 2 | Y5: IV | Z5: 1257 | AA5: 307 | AF5: 2 | AG5: IV | AH5: 1257 | AI5: 302 | AM5: 2 | AN5: IV | AO5: 1257 | AP5: 282 | AT5: 2 | AU5: GB | AV5: 1399 | AW5: 1365 | BA5: 2 | BB5: GB | BC5: 1399 | BD5: 1252 | BH5: 2 | BI5: GB | BJ5: 1399 | BK5: 1187 | BO5: 2 | BP5: GB | BQ5: 1399 | BR5: 1154 | BV5: 2 | BW5: GB | BX5: 1399 | BY5: 1101 | CC5: 2 | CD5: GB | CE5: 1399 | CF5: 954 | CJ5: 2 | CK5: GB | CL5: 1399 | CM5: 888 | CQ5: 2 | CR5: BG | CS5: 1435 | CT5: 173 | CX5: 2 | CY5: BG | CZ5: 1435 | DA5: 139 | DD5: 2 | DE5: IV | DF5: 1257 | DG5: 125 | DL5: 2 | DM5: BG | DN5: 1435 | DO5: 50 | DS5: 2 | DT5: PR | DU5: 1811 | DV5: 34 | DZ5: 2 | EA5: DG | EB5: 1594 | EC5: 64
B6: 3 | C6: BG | D6: 1331 | E6: 1064 | H6: 3 | I6: BG | J6: 1435 | K6: 485 | P6: 3 | Q6: BG | R6: 1416 | S6: 388 | X6: 3 | Y6: BG | Z6: 1416 | AA6: 388 | AF6: 3 | AG6: BG | AH6: 1416 | AI6: 388 | AM6: 3 | AN6: BG | AO6: 1416 | AP6: 388 | AT6: 3 | AU6: BG | AV6: 1455 | AW6: 413 | BA6: 3 | BB6: BG | BC6: 1455 | BD6: 413 | BH6: 3 | BI6: BG | BJ6: 1435 | BK6: 379 | BO6: 3 | BP6: BG | BQ6: 1435 | BR6: 388 | BV6: 3 | BW6: BG | BX6: 1435 | BY6: 351 | CC6: 3 | CD6: BG | CE6: 1435 | CF6: 250 | CJ6: 3 | CK6: BG | CL6: 1435 | CM6: 250 | CQ6: 3 | CR6: IV | CS6: 1257 | CT6: 121 | CX6: 3 | CY6: IV | CZ6: 1257 | DA6: 125 | DD6: 3 | DE6: GB | DF6: 1399 | DG6: 847 | DL6: 3 | DM6: GB | DN6: 1399 | DO6: 841 | DT6: PR | DV6: 758 | DZ6: 3 | EA6: IV | EB6: 1597 | EC6: 161
B7: 4 | C7: PR | D7: 1198 | E7: 220 | H7: 4 | I7: BG BIG | J7: 1416 | K7: 388 | P7: 4 | Q7: BG | R7: 1435 | S7: 485 | X7: 4 | Y7: BG | Z7: 1435 | AA7: 453 | AF7: 4 | AG7: BG | AH7: 1435 | AI7: 413 | AM7: 4 | AN7: BG | AO7: 1435 | AP7: 413 | AT7: 4 | AU7: BG | AV7: 1416 | AW7: 388 | BA7: 4 | BB7: BG | BC7: 1416 | BD7: 388 | BH7: 4 | BI7: BG | BJ7: 1415 | BK7: 100 | BO7: 4 | BP7: BG | BQ7: 1415 | BR7: 103 | BY7: =SUM(BY4:BY6) -> 1622 | CF7: 1374 | CM7: 1294 | CT7: =SUM(CT4:CT6) -> 1182 | DA7: =SUM(DA4:DA6) -> 1126 | DG7: =SUM(DG4:DG6) -> 1040 | DO7: =SUM(DO4:DO6) -> 975 | DT7: NB | DV7: 741 | DZ7: 4 | EA7: ST | EB7: 1604 | EC7: 540
BK8: =SUM(BK4:BK7) -> 1930 | BR8: =SUM(BR4:BR7) -> 1876 | BV8: 0.55 | CC8: 0.55 | CJ8: 0.55 | CQ8: 0.55 | DT8: NB | DV8: 389 | DZ8: 5 | EA8: GB | EB8: 1866 | EC8: 225
E9: =SUM(E4:E7) -> 3795 | H9: 5 | I9: BG BIG | J9: 1415 | K9: 652 | P9: 5 | Q9: BG BIG | R9: 1415 | S9: 652 | X9: 5 | Y9: BG BIG | Z9: 1415 | AA9: 652 | AF9: 5 | AG9: BG BIG | AH9: 1415 | AI9: 633 | AM9: 5 | AN9: BG BIG | AO9: 1415 | AP9: 633 | AT9: 5 | AU9: BG | AV9: 1415 | AW9: 633 | BA9: 5 | BB9: BG | BC9: 1415 | BD9: 633 | BH9: 0.55 | BO9: 0.55 | BV9: 4 | BW9: GB | BX9: 1397 | BY9: 78 | CC9: 4 | CD9: GB | CE9: 1441 | CF9: 30 | CJ9: 4 | CK9: TB | CL9: 1571 | CM9: 44 | CQ9: 4 | CR9: TB | CS9: 1571 | CT9: 44 | CX9: 0.55 | DD9: 0.55F | DE9: . | DL9: 0.55 | EC9: 1045
B10: 0.55 | K10: =SUM(K4:K9) -> 3556 | S10: =SUM(S4:S9) -> 3369 | AA10: =SUM(AA4:AA9) -> 3315 | AI10: =SUM(AI4:AI9) -> 3181 | AP10: =SUM(AP4:AP9) -> 3137 | AW10: =SUM(AW4:AW9) -> 3063 | BD10: =SUM(BD4:BD9) -> 2950 | BH10: 5 | BI10: IV | BJ10: 1573 | BK10: 305 | BO10: 5 | BP10: IV | BQ10: 1573 | BR10: 248 | BV10: 5 | BW10: GB | BX10: 1441 | BY10: 30 | CC10: 5 | CD10: GB | CE10: 1397 | CF10: 76 | CJ10: 5 | CK10: GB | CL10: 1441 | CM10: 30 | CQ10: 5 | CR10: GB | CS10: 1441 | CT10: 30 | CX10: 4 | CY10: IV | CZ10: 1441 | DA10: 30 | DD10: 4 | DE10: BB | DF10: 1577 | DG10: 27 | DL10: 4 | DM10: GB | DN10: 1414 | DO10: 30 | DS10: 3 | DT10: BB | DU10: 1577 | DV10: 14
B11: 5 | C11: IV | D11: 1390 | E11: 2113 | H11: 0.55 | Q11: 0.55 | Y11: 0.55 | AG11: 0.55 | AM11: 0.55 | AT11: 0.55 | BA11: 0.55 | BH11: 6 | BI11: IV | BJ11: 1570 | BK11: 129 | BO11: 6 | BP11: IV | BQ11: 1570 | BR11: 129 | BV11: 6 | BW11: TB | BX11: 1571 | BY11: 388 | CC11: 6 | CD11: TB | CE11: 1571 | CF11: 90 | CM11: 74 | CT11: =SUM(CT9:CT10) -> 74 | DA11: 30 | DD11: 5 | DE11: HMB | DF11: 1791 | DG11: 8 | DO11: =SUM(DO10) -> 30 | DV11: =SUM(DV4:DV10) -> 2714 | DZ11: 0.6
B12: 6 | C12: IV | D12: 1380 | E12: 933 | H12: 6 | I12: GB | J12: 1441 | K12: 609 | P12: 6 | Q12: IV | R12: 1503 | S12: 56 | X12: 6 | Y12: IV | Z12: 1503 | AA12: 56 | AF12: 6 | AG12: IV | AH12: 1503 | AI12: 37 | AM12: 6 | AN12: IV | AO12: 1539 | AP12: 488 | AT12: 6 | AU12: IV | AV12: 1573 | AW12: 1370 | BA12: 6 | BB12: IV | BC12: 1573 | BD12: 1340 | BH12: 7 | BI12: GB | BJ12: 1397 | BK12: 78 | BO12: 7 | BP12: GB | BQ12: 1397 | BR12: 78 | BV12: 7 | BW12: PR | BX12: 1598 | BY12: 5 | CC12: 7 | CD12: IV | CE12: 1573 | CF12: 67 | CJ12: 0.55 FULL | CQ12: 0.55F | DE12: NB | DG12: 741 | DZ12: 6 | EA12: IV | EB12: 1455 | EC12: 148
B13: 7 | C13: IV | D13: 1382 | E13: 126 | H13: 7 | I13: GB | J13: 1397 | K13: 78 | P13: 7 | Q13: IV | R13: 1521 | S13: 995 | X13: 7 | Y13: IV | Z13: 1521 | AA13: 1016 | AF13: 7 | AG13: IV | AH13: 1521 | AI13: 39 | AM13: 7 | AN13: IV | AO13: 1512 | AP13: 39 | AT13: 7 | AU13: IV | AV13: 1570 | AW13: 232 | BA13: 7 | BB13: IV | BC13: 1570 | BD13: 220 | BH13: 8 | BI13: GB | BJ13: 1441 | BK13: 30 | BO13: 8 | BP13: GB | BQ13: 1441 | BR13: 30 | BY13: =SUM(BY9:BY12) -> 501 | CF13: 263 | CJ13: 6 | CK13: GB | CL13: 1481 | CM13: 4 | CQ13: 6 | CR13: PL | CS13: 1760 | CT13: 101 | CX13: 0.55F | DE13: NB | DG13: 389 | DL13: 0.55FULL | DS13: 0.7 | EC13: 148
B14: 8 | C14: IV | D14: 1284 | E14: 65 | H14: 8 | I14: GB | J14: 1341 | K14: 27 | P14: 8 | Q14: IV 0.60 | R14: 1455 | S14: 161 | X14: 8 | Y14: IV 0.60 | Z14: 1445 | AA14: 161 | AF14: 8 | AG14: IV 0.60 | AH14: 1445 | AI14: 161 | AM14: 8 | AN14: IV | AO14: 1503 | AP14: 37 | AT14: 8 | AU14: GB | AV14: 1528 | AW14: 296 | BA14: 8 | BB14: GB | BC14: 1528 | BD14: 115 | BH14: 9 | BI14: NB | BJ14: 1554 | BK14: 76 | BO14: 9 | BP14: NB | BQ14: 1554 | BR14: 75 | BV14: 0.55F | CC14: 0.55 FULL | CJ14: 7 | CK14: TCR | CL14: 1508 | CM14: 9 | CQ14: 7 | CR14: HMB | CS14: 1791 | CT14: 8 | CX14: 5 | CY14: BG | CZ14: 1410 | DA14: 52 | DE14: PR | DG14: 105 | DL14: 5 | DM14: PR | DO14: 758 | DS14: 2 | DT14: IV | DU14: 1597 | DV14: 101
B15: 9 | C15: IV | D15: 1316 | E15: 48 | H15: 9 | I15: IV | J15: 1464 | K15: 1250 | P15: 9 | Q15: BG | R15: 1502 | S15: 1451 | X15: 9 | Y15: BG | Z15: 1502 | AA15: 1173 | AF15: 9 | AG15: BG | AH15: 1502 | AI15: 741 | AM15: 9 | AN15: GB | AO15: 1528 | AP15: 686 | AT15: 9 | AU15: GB | AV15: 1397 | AW15: 78 | BA15: 9 | BB15: GB | BC15: 1397 | BD15: 78 | BH15: 10 | BI15: HMB | BJ15: 1523 | BK15: 71 | BO15: 10 | BP15: TB | BQ15: 1571 | BR15: 699 | BV15: 8 | BW15: BG | BX15: 1410 | BY15: 52 | CC15: 8 | CD15: BB | CE15: 1577 | CF15: 149 | CJ15: 8 | CK15: BG | CL15: 1410 | CM15: 52 | CQ15: 8 | CR15: BG | CS15: 1410 | CT15: 52 | CX15: 6 | CY15: TCR | CZ15: 1811 | DA15: 109 | DE15: PR | DG15: 2172 | DL15: 6 | DM15: NB | DO15: 741 | DS15: 3 | DT15: DG | DU15: 1594 | DV15: 64 | DZ15: 0.55F
B16: 10 | C16: IV | D16: 1332 | E16: 37 | H16: 10 | I16: IV | J16: 1434 | K16: 181 | P16: 10 | Q16: BG | R16: 1423 | S16: 144 | X16: 10 | Y16: BG | Z16: 1423 | AA16: 109 | AF16: 10 | AG16: BG | AH16: 1423 | AI16: 109 | AM16: 10 | AN16: GB | AO16: 1397 | AP16: 78 | AT16: 10 | AU16: GB | AV16: 1441 | AW16: 30 | BA16: 10 | BB16: GB | BC16: 1441 | BD16: 30 | BH16: 11 | BI16: TB | BJ16: 1571 | BK16: 999 | BO16: 11 | BP16: BG | BQ16: 1423 | BR16: 90 | BV16: 9 | BW16: BG | BX16: 1586 | BY16: 33 | CC16: 9 | CD16: GB | CE16: 1481 | CF16: 8 | CM16: 65 | CQ16: 9 | CR16: TCR | CS16: 1508 | CT16: 9 | CY16: PR | CZ16: Lagos | DA16: 10308 | DE16: PR | DG16: 1314 | DL16: 7 | DM16: NB | DO16: 389 | DS16: 4 | DT16: ST | DU16: 1604 | DV16: 542 | DZ16: 7 | EA16: HMB | EB16: 1878 | EC16: 732
B17: 11 | C17: IV | D17: 1370 | E17: 56 | H17: 11 | I17: IV | J17: 1390 | K17: 38 | P17: 11 | Q17: TB | R17: 1443 | S17: 341 | X17: 11 | Y17: TB | Z17: 1443 | AA17: 96 | AF17: 11 | AG17: TB | AH17: 1443 | AI17: 52 | AM17: 11 | AN17: GB | AO17: 1441 | AP17: 30 | AT17: 11 | AU17: NB | AV17: 1554 | AW17: 1035 | BA17: 11 | BB17: NB | BC17: 1554 | BD17: 677 | BH17: 12 | BI17: BG | BJ17: 1423 | BK17: 97 | BR17: =SUM(BR10:BR16) -> 1349 | BV17: 10 | BW17: BB | BX17: 1577 | BY17: 194 | CC17: 10 | CD17: TCR | CE17: 1508 | CF17: 9 | CJ17: 0.6 | CQ17: 10 | CR17: TCR | CS17: 1789 | CT17: 1243 | CX17: 7 | CY17: HMB | CZ17: 1791 | DA17: 8 | DE17: PR | DG17: 957 | DL17: 8 | DM17: BB | DN17: 1577 | DO17: 27 | DS17: 5 | DT17: PR | DU17: 1552 | DV17: 55 | EA17: PR | EC17: 758
B18: 12 | C18: GB | D18: 1397 | E18: 1118 | H18: 12 | I18: IV | J18: 1380 | K18: 39 | P18: 12 | Q18: NB | R18: 1438 | S18: 44 | X18: 12 | Y18: NB | Z18: 1438 | AA18: 38 | AF18: 13 | AG18: GB | AH18: 1441 | AI18: 30 | AM18: 12 | AN18: BG | AO18: 1502 | AP18: 271 | AT18: 12 | AU18: HMB | AV18: 1523 | AW18: 343 | BA18: 12 | BB18: HMB | BC18: 1523 | BD18: 711 | BK18: =SUM(BK10:BK17) -> 1785 | BO18: 0.55 FULL | BV18: 11 | BW18: GB | BX18: 1481 | BY18: 21 | CC18: 11 | CD18: BG | CE18: 1586 | CF18: 33 | CJ18: 9 | CK18: IV | CL18: 1445 | CM18: 161 | CQ18: 11 | CR18: TCR | CS18: 1790 | CT18: 2263 | CX18: 8 | CY18: BB | CZ18: 1577 | DA18: 27 | DE18: PR | DG18: 758 | DL18: 9 | DM18: HMB | DN18: 1791 | DO18: 8 | DT18: GB | DU18: 1866 | DV18: 405 | EA18: NB | EC18: 741
B19: 13 | C19: GB | D19: 1330 | E19: 47 | H19: 13 | I19: IV | J19: 1440 | K19: 63 | P19: 13 | Q19: GB | R19: 1441 | S19: 398 | X19: 13 | Y19: GB | Z19: 1441 | AA19: 30 | AF19: 14 | AG19: GB | AH19: 1397 | AI19: 78 | AM19: 13 | AN19: BG | AO19: 1423 | AP19: 109 | AT19: 13 | AU19: TB | AV19: 1443 | AW19: 52 | BA19: 14 | BB19: TB | BC19: 1571 | BD19: 1579 | BH19: 0.55 FULL | BO19: 12 | BP19: BG | BQ19: 1586 | BR19: 56 | BV19: 12 | BW19: PR | BX19: 1508 | BY19: 11 | CC19: 12 | CD19: BG | CE19: 1410 | CF19: 52 | CM19: 161 | CQ19: 12 | CR19: GB | CS19: 1481 | CT19: 4 | DA19: =SUM(DA14:DA18) -> 10504 | DD19: 6 | DE19: TCR | DF19: 1811 | DG19: 102 | DO19: =SUM(DO14:DO18) -> 1923 | DV19: =SUM(DV14:DV18) -> 1167 | EA19: NB | EC19: 389
B20: 14 | C20: BG | D20: 1398 | E20: 1788 | H20: 14 | I20: NB | J20: 1438 | K20: 180 | P20: 14 | Q20: GB | R20: 1397 | S20: 78 | X20: 14 | Y20: GB | Z20: 1397 | AA20: 78 | AF20: 15 | AG20: ST | AH20: 1371 | AI20: 165 | AM20: 14 | AN20: HMB | AO20: 1523 | AP20: 528 | AT20: 14 | AU20: TB | AV20: 1571 | AW20: 1784 | BA20: 15 | BB20: BG | BC20: 1558 | BD20: 299 | BH20: 13 | BI20: BG | BJ20: 1586 | BK20: 56 | BO20: 13 | BP20: IV | BQ20: 1609 | BR20: 334 | BY20: =SUM(BY15:BY19) -> 311 | CF20: 251 | CJ20: 0.7 | CT20: =SUM(CT13:CT19) -> 3680 | DG20: =SUM(DG10:DG19) -> 6573 | DZ20: 8 | EA20: HMB | EB20: 1791 | EC20: 8
B21: 15 | C21: BG | D21: 1326 | E21: 40 | H21: 15 | I21: PR | J21: 1394 | K21: 242 | P21: 15 | Q21: ST | R21: 1371 | S21: 719 | X21: 15 | Y21: ST | Z21: 1371 | AA21: 270 | AF21: 16 | AG21: GB | AH21: 1528 | AI21: 1053 | AM21: 15 | AN21: NB | AO21: 1554 | AP21: 1955 | AT21: 15 | AU21: BG | AV21: 1558 | AW21: 1152 | BA21: 16 | BB21: BG | BC21: 1502 | BD21: 176 | BH21: 14 | BI21: IV | BJ21: 1609 | BK21: 328 | BO21: 14 | BP21: BG | BQ21: 1410 | BR21: 52 | BV21: 0.6 | CC21: 0.6 | CJ21: 10 | CK21: ST | CL21: 1604 | CM21: 963 | CQ21: 0.6 | CX21: 0.6 | DL21: 0.6 | DS21: 0.6 | DZ21: 9 | EA21: BB | EB21: 1577 | EC21: 114
B22: 16 | C22: HMB | D22: 1354 | E22: 662 | H22: 16 | I22: BG | J22: 1423 | K22: 459 | S22: =SUM(S12:S21) -> 4387 | X22: 16 | Y22: GB | Z22: 1528 | AA22: 1694 | AG22: GB | AH22: 1539 | AI22: 1048 | AM22: 16 | AN22: TB | AO22: 1443 | AP22: 52 | AT22: 16 | AU22: BG | AV22: 1502 | AW22: 213 | BA22: 18 | BB22: BG | BC22: 1423 | BD22: 109 | BH22: 15 | BI22: BG | BJ22: 1410 | BK22: 52 | BO22: 15 | BP22: TC R | BQ22: 1598 | BR22: 28 | BV22: 13 | BW22: IV | BX22: 1445 | BY22: 110 | CC22: 13 | CD22: IV | CE22: 1455 | CF22: 161 | CJ22: 11 | CK22: IV | CL22: 1597 | CM22: 101 | CQ22: 13 | CR22: IV | CS22: 1455 | CT22: 161 | CX22: 9 | CY22: IV | CZ22: 1455 | DA22: 148 | DD22: 0.55 | DL22: 10 | DM22: IV | DN22: 1455 | DO22: 148 | DS22: 6 | DT22: IV | DU22: 1455 | DV22: 148 | EC22: =SUM(EC16:EC21) -> 2742
